<!DOCTYPE html>
<html lang="en">
<head><script src="/livereload.js?mindelay=10&amp;v=2&amp;port=1313&amp;path=livereload" data-no-instant defer></script>
  
    <title>Java&#39;s CompleteableFuture exception handling: whenComplete vs. handle :: dempkow.ski</title>
  
  <meta http-equiv="content-type" content="text/html; charset=utf-8">
<meta name="viewport" content="width=device-width, initial-scale=1.0">
<meta name="description" content="Today I learned about the behavior of thrown exceptions within asynchronous code using Java&rsquo;s CompletableFutures.
The question I had was:
Is it possible to have a CompletableFuture which calls something like .handle(), but returns Void?
I was writing code that wanted to basically handle exceptional cases, but not propagate those exceptions outwards.
I had written something like:
CompletableFuture.supplyAsync(() -&gt; { throw new RuntimeException(); }).handle((i, err) -&gt; { if (err != null) { throw new RuntimeException(err); } else { System.out.println(i); return i; } }).join(); And since handle is defined as taking in a BiFunction: (T, Throwable) -&gt; U:
" />
<meta name="keywords" content="" />

  <meta name="robots" content="noodp" />

<link rel="canonical" href="//localhost:1313/blog/java-completablefuture-exception-handling/" />





  
  <link rel="stylesheet" href="//localhost:1313/css/buttons.min.2bc533403a27dfe0e93105a92502b42ce4587e2e4a87d9f7d349e51e16e09478.css">

  
  <link rel="stylesheet" href="//localhost:1313/css/code.min.00125962708925857e7b66dbc58391d55be1191a3d0ce2034de8c9cd2c481c36.css">

  
  <link rel="stylesheet" href="//localhost:1313/css/fonts.min.4881f0c525f3ce2a1864fb6e96676396cebe1e6fcef1933e8e1dde7041004fb5.css">

  
  <link rel="stylesheet" href="//localhost:1313/css/footer.min.2e3eb191baee58dd05a9f0104ac1fab0827bca7c64dafe0b2579f934c33a1d69.css">

  
  <link rel="stylesheet" href="//localhost:1313/css/gist.min.a751e8b0abe1ba8bc53ced52a38b19d8950fe78ca29454ea8c2595cf26aad5c0.css">

  
  <link rel="stylesheet" href="//localhost:1313/css/header.min.7f345d8c226003a94bb7454f047dd5766f84d4a0b6cf516f4c5336ba6b59da9b.css">

  
  <link rel="stylesheet" href="//localhost:1313/css/main.min.ee92b43625bf71a7aac47c60d085d1fb1701670ae4dc91b7e90353b0be530bb2.css">

  
  <link rel="stylesheet" href="//localhost:1313/css/menu.min.36d82b6f304492b9d900e9bf2ec5244ba93481625a48a72783026543b1a84545.css">

  
  <link rel="stylesheet" href="//localhost:1313/css/pagination.min.82f6400eae7c7c6dc3c866733c2ec0579e4089608fea69400ff85b3880aa0d3c.css">

  
  <link rel="stylesheet" href="//localhost:1313/css/post.min.fc74ca360273c1d828da3c02b8174eba435607b369d98418ccc6f2243cd4e75d.css">

  
  <link rel="stylesheet" href="//localhost:1313/css/prism.min.d30415adfcea5d941e12586c2662e3969ab084def4e306af270817bde24dbb86.css">

  
  <link rel="stylesheet" href="//localhost:1313/css/syntax.min.cc789ed9377260d7949ea4c18781fc58959a89287210fe4edbff44ebfc1511b6.css">

  
  <link rel="stylesheet" href="//localhost:1313/css/terminal.min.109305be46ecc8c8a546226b2f090dffa26d48d13167fd307dd858181df9ae28.css">

  
  <link rel="stylesheet" href="//localhost:1313/css/terms.min.b81791663c3790e738e571cdbf802312390d30e4b1d8dc9d814a5b5454d0ac11.css">







<link rel="shortcut icon" href="//localhost:1313/favicon.png">
<link rel="apple-touch-icon" href="//localhost:1313/apple-touch-icon.png">


<meta name="twitter:card" content="summary" />

  
    <meta name="twitter:site" content="" />
  
    <meta name="twitter:creator" content="" />



<meta property="og:locale" content="en" />
<meta property="og:type" content="article" />
<meta property="og:title" content="Java&#39;s CompleteableFuture exception handling: whenComplete vs. handle">
<meta property="og:description" content="Today I learned about the behavior of thrown exceptions within asynchronous code using Java&rsquo;s CompletableFutures.
The question I had was:
Is it possible to have a CompletableFuture which calls something like .handle(), but returns Void?
I was writing code that wanted to basically handle exceptional cases, but not propagate those exceptions outwards.
I had written something like:
CompletableFuture.supplyAsync(() -&gt; { throw new RuntimeException(); }).handle((i, err) -&gt; { if (err != null) { throw new RuntimeException(err); } else { System.out.println(i); return i; } }).join(); And since handle is defined as taking in a BiFunction: (T, Throwable) -&gt; U:
" />
<meta property="og:url" content="//localhost:1313/blog/java-completablefuture-exception-handling/" />
<meta property="og:site_name" content="dempkow.ski" />

  <meta property="og:image" content="//localhost:1313/og-image.png">

<meta property="og:image:width" content="1200">
<meta property="og:image:height" content="627">


  <meta property="article:published_time" content="2017-10-20 23:00:15 -0400 EDT" />












</head>
<body>


<div class="container center">

  <header class="header">
  <div class="header__inner">
    <div class="header__logo">
      <a href="/">
  <div class="logo">
    dempkow.ski
  </div>
</a>

    </div>
    
      <ul class="menu menu--mobile">
  <li class="menu__trigger">Menu&nbsp;â–¾</li>
  <li>
    <ul class="menu__dropdown">
      
        
          <li><a href="/about">About</a></li>
        
      
        
          <li><a href="/blog">Blog</a></li>
        
      
      
    </ul>
  </li>
</ul>

    
    
  </div>
  
    <nav class="navigation-menu">
  <ul class="navigation-menu__inner menu--desktop">
    
      
        
          <li><a href="/about" >About</a></li>
        
      
        
          <li><a href="/blog" >Blog</a></li>
        
      
      
    
  </ul>
</nav>

  
</header>


  <div class="content">
    
<article class="post">
  <h1 class="post-title">
    <a href="//localhost:1313/blog/java-completablefuture-exception-handling/">Java&rsquo;s CompleteableFuture exception handling: whenComplete vs. handle</a>
  </h1>
  <div class="post-meta"><time class="post-date">2017-10-20</time><span class="post-reading-time">3 min read (633 words)</span></div>

  
  


  

  <div class="post-content"><div>
        <p>Today I learned about the behavior of thrown exceptions within asynchronous code using Java&rsquo;s CompletableFutures.</p>
<p>The question I had was:</p>
<blockquote>
<p>Is it possible to have a CompletableFuture which calls something like <code>.handle()</code>, but returns <code>Void</code>?</p>
</blockquote>
<p>I was writing code that wanted to basically handle exceptional cases, but not propagate those exceptions outwards.</p>
<p>I had written something like:</p>
<div class="highlight"><pre tabindex="0" style="color:#f8f8f2;background-color:#272822;-moz-tab-size:4;-o-tab-size:4;tab-size:4;"><code class="language-java" data-lang="java"><span style="display:flex;"><span>CompletableFuture.<span style="color:#a6e22e">supplyAsync</span>(() <span style="color:#f92672">-&gt;</span> {
</span></span><span style="display:flex;"><span>  <span style="color:#66d9ef">throw</span> <span style="color:#66d9ef">new</span> RuntimeException();
</span></span><span style="display:flex;"><span>}).<span style="color:#a6e22e">handle</span>((i, err) <span style="color:#f92672">-&gt;</span> {
</span></span><span style="display:flex;"><span>  <span style="color:#66d9ef">if</span> (err <span style="color:#f92672">!=</span> <span style="color:#66d9ef">null</span>) {
</span></span><span style="display:flex;"><span>    <span style="color:#66d9ef">throw</span> <span style="color:#66d9ef">new</span> RuntimeException(err);
</span></span><span style="display:flex;"><span>  } <span style="color:#66d9ef">else</span> {
</span></span><span style="display:flex;"><span>    System.<span style="color:#a6e22e">out</span>.<span style="color:#a6e22e">println</span>(i);
</span></span><span style="display:flex;"><span>    <span style="color:#66d9ef">return</span> i;
</span></span><span style="display:flex;"><span>  }
</span></span><span style="display:flex;"><span>}).<span style="color:#a6e22e">join</span>();
</span></span></code></pre></div><p>And since <code>handle</code> is defined as taking in a <code>BiFunction: (T, Throwable) -&gt; U</code>:</p>
<div class="highlight"><pre tabindex="0" style="color:#f8f8f2;background-color:#272822;-moz-tab-size:4;-o-tab-size:4;tab-size:4;"><code class="language-java" data-lang="java"><span style="display:flex;"><span><span style="color:#f92672">&lt;</span>U<span style="color:#f92672">&gt;</span> CompletableFuture<span style="color:#f92672">&lt;</span>U<span style="color:#f92672">&gt;</span> <span style="color:#a6e22e">handle</span>(BiFunction<span style="color:#f92672">&lt;?</span> <span style="color:#66d9ef">super</span> T,Throwable,<span style="color:#f92672">?</span> <span style="color:#66d9ef">extends</span> U<span style="color:#f92672">&gt;</span> fn)
</span></span></code></pre></div><p>We&rsquo;re stuck with an unnecessary <code>return i</code> in our code, even though we don&rsquo;t care about the result of the <code>handle</code>. In this case we&rsquo;re just logging on success. The question was then raised:</p>
<blockquote>
<p>Why not use <code>whenComplete</code>?</p>
</blockquote>
<p>Whose signature looks like:</p>
<div class="highlight"><pre tabindex="0" style="color:#f8f8f2;background-color:#272822;-moz-tab-size:4;-o-tab-size:4;tab-size:4;"><code class="language-java" data-lang="java"><span style="display:flex;"><span>CompletableFuture<span style="color:#f92672">&lt;</span>T<span style="color:#f92672">&gt;</span> <span style="color:#a6e22e">whenComplete</span>(BiConsumer<span style="color:#f92672">&lt;?</span> <span style="color:#66d9ef">super</span> T,<span style="color:#f92672">?</span> <span style="color:#66d9ef">super</span> Throwable<span style="color:#f92672">&gt;</span> action)
</span></span></code></pre></div><p>And well, for one that doesn&rsquo;t actually solve my problem, as I still need to return something out of the <code>whenComplete</code>, but it also raised the question of what would happen in the exceptional case, and why do these two seemingly similar methods even exist?</p>
<p>The answer here is somewhat that they handle errors differently. If we look at the <em>totally clear</em> JavaDocs for <code>handle</code>:</p>
<blockquote>
<p>When this stage is complete, the given function is invoked with the result (or null if none) and the exception (or null if none) of this stage as arguments, and the function&rsquo;s result is used to complete the returned stage.</p>
</blockquote>
<p>and for <code>whenComplete</code>:</p>
<blockquote>
<p>When this stage is complete, the given action is invoked with the result (or null if none) and the exception (or null if none) of this stage as arguments. The returned stage is completed when the action returns. If the supplied action itself encounters an exception, then the returned stage exceptionally completes with this exception unless this stage also completed exceptionally.</p>
</blockquote>
<p>It&rsquo;s totally clear what happens right? I mean from reading those two blurbs I&rsquo;m sure you could easily predict the result of this snippet:</p>
<div class="highlight"><pre tabindex="0" style="color:#f8f8f2;background-color:#272822;-moz-tab-size:4;-o-tab-size:4;tab-size:4;"><code class="language-java" data-lang="java"><span style="display:flex;"><span>CompletableFuture.<span style="color:#a6e22e">supplyAsync</span>(() <span style="color:#f92672">-&gt;</span> {
</span></span><span style="display:flex;"><span>  <span style="color:#66d9ef">throw</span> <span style="color:#66d9ef">new</span> RuntimeException(<span style="color:#e6db74">&#34;1&#34;</span>);
</span></span><span style="display:flex;"><span>}).<span style="color:#a6e22e">whenComplete</span>((i, err) <span style="color:#f92672">-&gt;</span> {
</span></span><span style="display:flex;"><span>  System.<span style="color:#a6e22e">out</span>.<span style="color:#a6e22e">println</span>(<span style="color:#e6db74">&#34;hello&#34;</span>);
</span></span><span style="display:flex;"><span>  <span style="color:#66d9ef">throw</span> <span style="color:#66d9ef">new</span> RuntimeException(<span style="color:#e6db74">&#34;2&#34;</span>);
</span></span><span style="display:flex;"><span>}).<span style="color:#a6e22e">join</span>();
</span></span></code></pre></div><p>You might assume that you&rsquo;d get back <code>RuntimeException(&quot;2&quot;)</code> since thats the last thing thrown in the chain, and it seems like <code>whenComplete</code> takes in an error, so that&rsquo;s probably not just hanging around, right? Well, if we run the code we see:</p>
<div class="highlight"><pre tabindex="0" style="color:#f8f8f2;background-color:#272822;-moz-tab-size:4;-o-tab-size:4;tab-size:4;"><code class="language-java" data-lang="java"><span style="display:flex;"><span>hello
</span></span><span style="display:flex;"><span>Exception in thread <span style="color:#e6db74">&#34;main&#34;</span> java.<span style="color:#a6e22e">util</span>.<span style="color:#a6e22e">concurrent</span>.<span style="color:#a6e22e">CompletionException</span>: java.<span style="color:#a6e22e">lang</span>.<span style="color:#a6e22e">RuntimeException</span>: 1
</span></span><span style="display:flex;"><span>	at java.<span style="color:#a6e22e">util</span>.<span style="color:#a6e22e">concurrent</span>.<span style="color:#a6e22e">CompletableFuture</span>.<span style="color:#a6e22e">encodeThrowable</span>(CompletableFuture.<span style="color:#a6e22e">java</span>:273)
</span></span><span style="display:flex;"><span>	at java.<span style="color:#a6e22e">util</span>.<span style="color:#a6e22e">concurrent</span>.<span style="color:#a6e22e">CompletableFuture</span>.<span style="color:#a6e22e">completeThrowable</span>(CompletableFuture.<span style="color:#a6e22e">java</span>:280)
</span></span><span style="display:flex;"><span>	at java.<span style="color:#a6e22e">util</span>.<span style="color:#a6e22e">concurrent</span>.<span style="color:#a6e22e">CompletableFuture$AsyncSupply</span>.<span style="color:#a6e22e">run</span>(CompletableFuture.<span style="color:#a6e22e">java</span>:1592)
</span></span></code></pre></div><p>What even happened here to see this output? We see <code>hello</code>, so we know that the code from the <code>whenComplete</code> block executed, but that exception looks like it&rsquo;s from the <code>supplyAsync</code> call. So not only did our second exception simply disappear, but <code>whenComplete</code> also wrapped our inital exception in a <code>CompletionException</code>. Fantastic.</p>
<p>Imagine if we had wanted to handle that error somehow, and done something like:</p>
<div class="highlight"><pre tabindex="0" style="color:#f8f8f2;background-color:#272822;-moz-tab-size:4;-o-tab-size:4;tab-size:4;"><code class="language-java" data-lang="java"><span style="display:flex;"><span>CompletableFuture.<span style="color:#a6e22e">supplyAsync</span>(() <span style="color:#f92672">-&gt;</span> {
</span></span><span style="display:flex;"><span>  <span style="color:#66d9ef">throw</span> <span style="color:#66d9ef">new</span> RuntimeException(<span style="color:#e6db74">&#34;1&#34;</span>);
</span></span><span style="display:flex;"><span>  <span style="color:#66d9ef">return</span> 1;
</span></span><span style="display:flex;"><span>}).<span style="color:#a6e22e">whenComplete</span>((i, err) <span style="color:#f92672">-&gt;</span> {
</span></span><span style="display:flex;"><span>  <span style="color:#66d9ef">if</span> (err <span style="color:#f92672">!=</span> <span style="color:#66d9ef">null</span>) {
</span></span><span style="display:flex;"><span>    <span style="color:#66d9ef">throw</span> <span style="color:#66d9ef">new</span> IllegalArgumentException(err.<span style="color:#a6e22e">getMessage</span>());
</span></span><span style="display:flex;"><span>  }
</span></span><span style="display:flex;"><span>}).<span style="color:#a6e22e">join</span>();
</span></span></code></pre></div><p>Well again, all we&rsquo;re going to get back is our original exception:</p>
<pre tabindex="0"><code>Exception in thread &#34;main&#34; java.util.concurrent.CompletionException: java.lang.RuntimeException: 1
</code></pre><p>So what did we learn?</p>
<ol>
<li>There doesn&rsquo;t seem to be a great way to handle exceptions while returning <code>CompletableFuture&lt;Void&gt;</code></li>
<li>If we want to actually handle any errors specially, we need to use <code>handle</code> which explicitly doesn&rsquo;t propagate errors for us, instead allowing us to take action on errors explicitly. This means we can either squash them, or propagate changed versions of them.</li>
<li><code>CompletionException</code>s are basically going to spring up in our code when using <code>CompletableFuture</code>s and there&rsquo;s not a whole lot we can do about it, besides liberally using <code>handle</code>? We can also use <code>exceptionally</code> to deal with this problem, but we can save that for another post.</li>
</ol>

      </div></div>

  
    

  

  
    

  
</article>

  </div>

  
    <footer class="footer">
  <div class="footer__inner">
    
      <div class="copyright">
        <span>Â© 2024 Powered by <a href="https://gohugo.io">Hugo</a></span>
    
      <span>:: <a href="https://github.com/panr/hugo-theme-terminal" target="_blank">Theme</a> made by <a href="https://github.com/panr" target="_blank">panr</a></span>
      </div>
  </div>
</footer>






<script type="text/javascript" src="/bundle.min.js"></script>





  
</div>

</body>
</html>
